<testsuite errors="0" failures="1" name="Django Project Tests" skips="0" tests="5" time="65.114"><testcase classname="whatever.tests.test_models.WhateverTest" name="test_whatever_creation" time="0.003003" /><testcase classname="whatever.tests.test_views.WhateverTest" name="test_invalid_form" time="0.005001" /><testcase classname="whatever.tests.test_views.WhateverTest" name="test_valid_form" time="0.004001"><failure message="False is not true" type="builtins.AssertionError">Traceback (most recent call last):
  File "C:\Users\netflixSterling\Desktop\djangotests\whatever\tests\test_views.py", line 29, in test_valid_form
    self.assertTrue(form.is_valid())
AssertionError: False is not true
</failure></testcase><testcase classname="whatever.tests.test_views.WhateverTest" name="test_whatever_list_view" time="0.710172" /><testcase classname="whatever.tests.test_views.MySeleniumTests" name="test_signup_fire" time="6.672104" /></testsuite>